{
  "error": "Hata: HTTPConnectionPool(host='localhost', port=11434): Max retries exceeded with url: /api/generate (Caused by NewConnectionError('<urllib3.connection.HTTPConnection object at 0x104ddb770>: Failed to establish a new connection: [Errno 61] Connection refused'))",
  "analiz_tarihi": "24.03.2025 14:47"
}